Workbook

Sheet Sheet2
D3: Values
A4: MPS ID | B4: Stage | C4: Current TAT (S50 onward) | D4: Count of S200 TAT | E4: Count of S300A TAT | F4: Count of S300 TAT | G4: Count of S600 TAT | H4: Count of S650 TAT
A5: Bibri, Simon Elias | B5: S300 | C5: 32 | D5: 1 | E5: 1 | F5: 1
A6: Metsoc Vol-I-8771046 | B6: S300 | C6: 32 | D6: 1 | E6: 1 | F6: 1 | G6: 1
A7: Metsoc Vol-II-8771047 | B7: S300 | C7: 32 | D7: 1 | E7: 1 | F7: 1
A8: Metsoc Vol-IV-8771049 | B8: S300 | C8: 35 | D8: 1 | E8: 1 | F8: 1
A9: Metsoc Vol-V-8771050 | B9: S300 | C9: 40 | D9: 1 | E9: 1 | F9: 1
A10: Metsoc Vol-VII-8771052 | B10: S300 | C10: 40 | D10: 1 | E10: 1 | F10: 1 | G10: 1
A11: Metsoc Vol-VIII-8771060 | B11: S300 | C11: 34 | D11: 1 | E11: 1 | F11: 1
A12: Grand Total | D12: 7 | E12: 7 | F12: 7 | G12: 2

Sheet Current Status
A1: S. no | B1: Book ID | C1: MPS ID | D1: Stage | E1: Received Date (S50) | F1: Current TAT (S50 onward) | G1: S200 TAT | H1: S300A TAT | I1: S300 TAT | J1: S600 TAT | K1: S650A TAT | L1: S650 TAT | M1: Total Chapters | N1: MS Pages | O1: Status - S200 | P1: Status - 300 | Q1: Remarks | R1: Column1 | S1: Plateform | T1: Column2
A2: =ROW()-1 -> 1 | B2: 705744_1_En | C2: Sánchez, Angeles | D2: S600 | E2: 46258 | F2: =TODAY()-E2 -> 65 | G2: =DATE(2026,9,19)-DATE(2026,8,24) -> 26 | H2: =DATE(2026,10,22)-DATE(2026,9,19) -> 33 | I2: =DATE(2026,10,24)-DATE(2026,10,22) -> 2 | J2: =TODAY()-DATE(2026,10,25) -> 3 | M2: 32 | N2: 500 | O2: S200 - Login : 00 Chapters; PE : 00 Chapters; CE : 00 Chapters; Comp : 00 Chapters; Online Delivery : 00 Chapters | P2: 28 Chaps-Rev.delivered, 3 Part in Eproof, FM-recept error | Q2: GraySci-Template issue resolved on 6-Oct.Pls follow Instruction of Janet provided on 22-Oct. Chap-09- "There are some things that need to be revised: 1. The keywords for the Pasuruan regency should be Pasuruan Regency. Big R for Regency. 2. Images on Figures 6 and 7 were reversed; the image on Figure 7 should come first. 3. The captions on Figure 3.1 should be placed before Figure 1. 4. The captions on Figure 4.1 should be placed before Figure 13. | R2: FM1 receipt error | S2: Word
A3: =ROW()-1 -> 2 | B3: 696264_1_En | C3: Metsoc Vol-I-8771046 | D3: S300 | E3: 46291 | F3: =TODAY()-E3 -> 32 | G3: =DATE(2026,10,10)-DATE(2026,9,26) -> 14 | H3: =DATE(2026,10,24)-DATE(2026,10,10) -> 14 | I3: =DATE(2026,10,27)-DATE(2026,10,25) -> 2 | J3: =TODAY()-DATE(2026,10,28) -> 0 | M3: 15 | N3: 200 | O3: S200 - Login : 00 Chapters; PE : 00 Chapters; CE : 00 Chapters; Comp : 00 Chapters; Online Delivery : 00 Chapters | P3: Delivered on 27th | Q3: email sent to PE (MS ISSUE) | R3: Delayed from VE | S3: Word
A4: =ROW()-1 -> 3 | B4: 696260_1_En | C4: Metsoc Vol-II-8771047 | D4: S600 | E4: 46291 | F4: =TODAY()-E4 -> 32 | G4: =DATE(2026,10,12)-DATE(2026,9,26) -> 16 | H4: =DATE(2026,10,22)-DATE(2026,10,12) -> 10 | I4: =DATE(2026,10,28)-DATE(2026,10,23) -> 5 | J4: =TODAY()-DATE(2026,10,28) -> 0 | M4: 15 | N4: 200 | O4: S200 - Login : 00 Chapters; PE : 00 Chapters; CE : 00 Chapters; Comp : 00 Chapters; Online Delivery : 00 Chapters | Q4: email sent to PE (MS ISSUE) | S4: Word
A5: =ROW()-1 -> 4 | B5: 695444_1_En | C5: Metsoc Vol-III-8771048 | D5: S600 | E5: 46288 | F5: =TODAY()-E5 -> 35 | G5: =DATE(2026,10,8)-DATE(2026,9,23) -> 15 | H5: =DATE(2026,10,24)-DATE(2026,10,8) -> 16 | I5: =DATE(2026,10,26)-DATE(2026,10,25) -> 1 | J5: =TODAY()-DATE(2026,10,27) -> 1 | M5: 31 | N5: 280 | O5: S200 - Login : 00 Chapters; PE : 00 Chapters; CE : 00 Chapters; Comp : 00 Chapters; Online Delivery : 00 Chapters | P5: S300 completed | Q5: PRR Sent on 15th Sep | R5: FM1 receipt error | S5: Word
A6: =ROW()-1 -> 5 | B6: 695897_1_En | C6: Metsoc Vol-IV-8771049 | D6: S300 | E6: 46288 | F6: =TODAY()-E6 -> 35 | G6: =DATE(2026,10,14)-DATE(2026,10,2) -> 12 | H6: =DATE(2026,10,27)-DATE(2026,10,14) -> 13 | I6: =TODAY()-DATE(2026,10,28) -> 0 | M6: 25 | N6: 240 | O6: S200 - Login : 00 Chapters; PE : 00 Chapters; CE : 00 Chapters; Comp : 00 Chapters; Online Delivery : 00 Chapters | P6: 5 chap in Revises | Q6: PRR Sent on 15th Sep, Job Sheet updated for missing chapters and TOC on 10-Oct | R6: Final Manuscript recd on 20th Oct | S6: Word
A7: =ROW()-1 -> 6 | B7: 696258_1_En | C7: Metsoc Vol-V-8771050 | D7: S300 | E7: 46283 | F7: =TODAY()-E7 -> 40 | G7: =DATE(2026,10,7)-DATE(2026,9,21) -> 16 | H7: =DATE(2026,10,24)-DATE(2026,10,8) -> 16 | I7: =DATE(2026,10,28)-DATE(2026,10,25) -> 3 | M7: 25 | N7: 244 | O7: S200 - Login : 00 Chapters; PE : 00 Chapters; CE : 00 Chapters; Comp : 00 Chapters; Online Delivery : 00 Chapters | P7: Delivered S300 on 28-Oct | Q7: PRR Sent on 15th Sep, | R7: Chap-04 removed as per author instructions | S7: Word
A8: =ROW()-1 -> 7 | B8: 696262_1_En | C8: Metsoc Vol-VI-8771051 | D8: S650A | E8: 46283 | F8: =TODAY()-E8 -> 40 | G8: =DATE(2026,10,7)-DATE(2026,9,21) -> 16 | H8: =DATE(2026,10,19)-DATE(2026,10,12) -> 7 | I8: =TODAY()-DATE(2026,10,20) -> 8 | J8: =DATE(2026,10,26)-DATE(2026,10,22) -> 4 | K8: =TODAY()-DATE(2026,10,27) -> 1 | M8: 9 | N8: 100 | O8: S200 - Login : 00 Chapters; PE : 00 Chapters; CE : 00 Chapters; Comp : 00 Chapters; Online Delivery : 00 Chapters | Q8: PRR Sent on 15th Sep | S8: Word
A9: =ROW()-1 -> 8 | B9: 695893_1_En | C9: Metsoc Vol-VII-8771052 | D9: S600 | E9: 46283 | F9: =TODAY()-E9 -> 40 | G9: =DATE(2026,10,9)-DATE(2026,9,21) -> 18 | H9: =DATE(2026,10,24)-DATE(2026,10,12) -> 12 | I9: =DATE(2026,10,28)-DATE(2026,10,25) -> 3 | J9: =TODAY()-DATE(2026,10,28) -> 0 | M9: 13 | N9: 120 | O9: S200 - Login : 00 Chapters; PE : 00 Chapters; CE : 00 Chapters; Comp : 00 Chapters; Online Delivery : 00 Chapters | P9: Delivrered | Q9: PRR Sent on 15th Sep | S9: Word
A10: =ROW()-1 -> 9 | B10: 696253_1_En | C10: Metsoc Vol-VIII-8771060 | D10: S300 | E10: 46289 | F10: =TODAY()-E10 -> 34 | G10: =TODAY()-DATE(2026,9,25) -> 33 | H10: =DATE(2026,10,24)-DATE(2026,10,12) -> 12 | I10: =TODAY()-DATE(2026,10,25) -> 3 | M10: 37 | N10: 200 | O10: S200 - Login : 00 Chapters; PE : 00 Chapters; CE : 00 Chapters; Comp : 00 Chapters; Online Delivery : 00 Chapters | P10: All in revises | Q10: Received in Production on 18th Sep (2.50pm) | R10: Delayed from VE | S10: Word
A11: =ROW()-1 -> 10 | B11: 696263_1_En | C11: Metsoc-Vol-IX-8771159 | D11: S300A | E11: 46295 | F11: =TODAY()-E11 -> 28 | G11: =DATE(2026,10,27)-DATE(2026,10,12) -> 15 | H11: =TODAY()-DATE(2026,10,28) -> 0 | M11: 78 | N11: 750 | O11: S200 - Login :00 Chapters; PE : 00 Chapters; CE : 00 Chapters; Comp : 00 Chapters; Online Delivery : 00 Chapters | P11: 11 chaps in Revises | Q11: Query solved on 12-Oct(FM component recd. Autho & Aff missing in chap-60) | S11: Word
A12: =ROW()-1 -> 11 | B12: 708036_1_En | C12: Zhou, Kun-8770838 | D12: S300A | E12: 46293 | F12: =TODAY()-E12 -> 30 | G12: =DATE(2026,10,21)-DATE(2026,9,30) -> 21 | H12: =TODAY()-DATE(2026,10,26) -> 2 | M12: 81 | N12: 600 | O12: S200 - Login : 00 Chapters; PE : 00 Chapters; CE : 00 Chapters; Comp : 00 Chapters; Online Delivery : 00 Chapters | P12: 25 chap in Revises | Q12: PRR sent on 17th Sep | S12: Word
A13: =ROW()-1 -> 12 | B13: 702839_1_En | C13: Abarzhi, Snezhana I. | D13: S650 | E13: 46286 | F13: =TODAY()-E13 -> 37 | G13: =DATE(2026,10,7)-DATE(2026,9,21) -> 16 | H13: =TODAY()-DATE(2026,10,7) -> 21 | I13: =TODAY()-DATE(2026,10,23) -> 5 | J13: =DATE(2026,10,24)-DATE(2026,10,23) -> 1 | K13: =DATE(2026,10,27)-DATE(2026,10,26) -> 1 | L13: =TODAY()-DATE(2026,10,28) -> 0 | M13: 7 | N13: 100 | O13: S200 - Login : 00 Chapters; PE : 00 Chapters; CE : 00 Chapters; Comp : 00 Chapters; Online Delivery : 00 Chapters | P13: 2 in Eproof rest revises completed | Q13: PRR sent on 17th Sep. Query-Reference missing and content mismatch, One new manuscript approval | S13: Word
A14: =ROW()-1 -> 13 | B14: 704353_1_En | C14: Giordano, Andrea | D14: S650A | E14: 46282 | F14: =TODAY()-DATE(2026,9,17) -> 41 | G14: =DATE(2026,10,6)-DATE(2026,9,17) -> 19 | H14: =DATE(2026,10,21)-DATE(2026,10,8) -> 13 | I14: =DATE(2026,10,22)-DATE(2026,10,21) -> 1 | J14: =DATE(2026,10,24)-DATE(2026,10,23) -> 1 | K14: =TODAY()-DATE(2026,10,26) -> 2 | M14: 41 | N14: 500 | O14: S200 - Login : 00 Chapters; PE : 00 Chapters; CE : 00 Chapters; Comp : 00 Chapters; Online Delivery : 00 Chapters | Q14: PRR sent on 17th Sep | S14: Word
A15: =ROW()-1 -> 14 | B15: 708652_1_En | C15: García-Holgado, Alicia-8771063 | D15: S200 | E15: 46294 | F15: =TODAY()-E15 -> 29 | G15: =TODAY()-DATE(2026,10,3) -> 25 | M15: 36 | N15: 500 | O15: S200 - Login : 00 Chapters; PE : 15 Chapters; CE : 21 Chapters; Comp : 00 Chapters; Online Delivery : 00 Chapters | P15: Query will be resolved after 23-oct conferences | Q15: Hold for new manuscript solved. Will receive today | S15: Tex
A16: =ROW()-1 -> 15 | B16: 709492_1_En | C16: Trapani, Ferdinando | D16: S300A | E16: 46292 | F16: =TODAY()-E16 -> 31 | G16: =DATE(2026,10,27)-DATE(2026,9,28) -> 29 | H16: =TODAY()-DATE(2026,10,28) -> 0 | I16: =TODAY()-DATE(2026,10,28) -> 0 | M16: 31 | N16: 500 | O16: S200 - Login : 00 Chapters; PE : 00 Chapters; CE : 00 Chapters; Comp : 00 Chapters; Online Delivery : 00 Chapters | P16: S200 delivered on 27-Oct | S16: Word
A17: =ROW()-1 -> 16 | B17: 704172_1_En | C17: Bibri, Simon Elias | D17: S300 | E17: 46291 | F17: =TODAY()-E17 -> 32 | G17: =DATE(2026,10,22)-DATE(2026,9,28) -> 24 | H17: =DATE(2026,10,27)-DATE(2026,10,22) -> 5 | I17: =TODAY()-DATE(2026,10,28) -> 0 | M17: 28 | N17: 350 | O17: S200 - Login : 00 Chapters; PE : 00 Chapters; CE : 00 Chapters; Comp : 00 Chapters; Online Delivery : 00 Chapters | P17: 15 Chaps in Revises. | S17: Word
A18: =ROW()-1 -> 17 | B18: 710752_1_En | C18: Xu-MSEM-8771092-Tex | D18: S200 | E18: 46302 | F18: =TODAY()-E18 -> 21 | G18: =TODAY()-DATE(2026,10,21) -> 7 | M18: =129+6 -> 135 | N18: 1500 | O18: S200 - Login : 129 Chapters; PE : 00 Chapters; CE : 00 Chapters; Comp : 00 Chapters; Online Delivery : 00 Chapters | P18: Query for JS regarding mismatch in chaps. BM is also there+Index | Q18: Books should be spilit in Two vol-I and II in S600 stage | S18: Tex
A19: =ROW()-1 -> 18 | B19: 695571_1_En | C19: Kalmani, Vijay | D19: S200 | E19: 46295 | F19: =TODAY()-E19 -> 28 | G19: =TODAY()-DATE(2026,10,13) -> 15 | M19: 48 | N19: 550 | O19: S200 - Login : 00 Chapters; PE : 00 Chapters; CE : 13 Chapters; Comp : 35 Chapters; Online Delivery : 00 Chapters | P19: Login reinstated, workflow issue solved | S19: Tex+word
A20: =ROW()-1 -> 19 | B20: 706742_1_En | C20: Sahraoui, Zakaria-8770559 | D20: S200 | E20: 46295 | F20: =TODAY()-E20 -> 28 | G20: =TODAY()-DATE(2026,10,12) -> 16 | M20: 40 | N20: 450 | O20: S200 - Login : 01 Chapters; PE : 21 Chapters; CE : 18 Chapters; Comp : 00 Chapters; Online Delivery : 00 Chapters | Q20: Query chap 28. figs missing was reced. | S20: Word
A21: =ROW()-1 -> 20 | B21: 704411_1_En | C21: Karakoc-AEF-8770589 | D21: S200 | E21: 46307 | F21: =TODAY()-E21 -> 16 | M21: 31 | N21: 350 | O21: S200 - Login : 00 Chapters; PE : 30 Chapters; CE : 00 Chapters; Comp : 00 Chapters; Online Delivery : 00 Chapters | P21: Login moved on 29-Oct | Q21: New manuscript recd again and chap-31 added. On 12-Oct26. Preface & TOC(FM components missing), Index tagging for 2 chaps. missing reced on 28-oct | R21: FM & TOC will be recd in S200 stage | S21: Word
A22: =ROW()-1 -> 21 | B22: 710147_1_En | C22: Cheshmehzangi, Ali | D22: S200 | E22: 46307 | F22: =TODAY()-E22 -> 16 | G22: =TODAY()-DATE(2026,10,19) -> 9 | M22: 28 | N22: 500 | O22: S200 - Login : 00 Chapters; PE : 28 Chapters; CE : 00 Chapters; Comp : 00 Chapters; Online Delivery : 00 Chapters | S22: Word
A23: =ROW()-1 -> 22 | B23: 708159_1_En | C23: Martín-Rojas, Rodrigo | D23: S200 | E23: 46302 | F23: =TODAY()-E23 -> 21 | G23: =TRIM(TODAY()-DATE(2026,10,19)) -> 9 | M23: 36 | N23: 450 | O23: S200 - Login : 00 Chapters; PE : 00 Chapters; CE : 00 Chapters; Comp : 36 Chapters; Online Delivery : 00 Chapters
A24: =ROW()-1 -> 23 | B24: 707038_1_En | C24: Teba, Tarek | D24: S200 | E24: 46309 | F24: =TODAY()-E24 -> 14 | G24: =TODAY()-DATE(2026,10,22) -> 6 | M24: 42 | N24: 500 | O24: S200 - Login : 00 Chapters; PE : 42 Chapters; CE : 00 Chapters; Comp : 00 Chapters; Online Delivery : 00 Chapters | S24: Word
A25: =ROW()-1 -> 24 | B25: 708552_1_En | C25: Gunka, Volodymyr | D25: S200 | E25: 46312 | F25: =TODAY()-E25 -> 11 | G25: =TODAY()-DATE(2026,10,22) -> 6 | M25: 23 | N25: 350 | O25: S200 - Login : 00 Chapters; PE : 23 Chapters; CE : 00 Chapters; Comp : 00 Chapters; Online Delivery : 00 Chapters | S25: Word
A26: =ROW()-1 -> 25 | B26: 700862_1_En | C26: PERARNAU-DMD-Garcia-Sanchez | D26: S200 Login | E26: 46312 | F26: =TODAY()-E26 -> 11 | M26: 56 | N26: 300 | O26: S200 - Login : 47 Chapters; PE : 09 Chapters; CE : 00 Chapters; Comp : 00 Chapters; Online Delivery : 00 Chapters | S26: Tex
A27: =ROW()-1 -> 26 | B27: 713085_1_En | C27: Lo Presti, Davide | D27: S200 Login | E27: 46316 | F27: =TODAY()-E27 -> 7 | M27: 109 | N27: 350 | S27: Word
A28: =ROW()-1 -> 27 | B28: 710384_1_En | C28: De Marchi, Luca | D28: S200 Login | E28: 46316 | F28: =TODAY()-E28 -> 7 | G28: =TODAY()-DATE(2026,10,25) -> 3 | M28: 69 | N28: 400 | O28: S200 - Login : 36 Chapters; PE : 33 Chapters; CE : 00 Chapters; Comp : 00 Chapters; Online Delivery : 00 Chapters | S28: Tex
A29: =ROW()-1 -> 28 | B29: 713564_1_En | C29: AL-Emran-Ihalanayake Ranjith | D29: S200 | E29: 46312 | F29: =TODAY()-E29 -> 11 | G29: =TODAY()-DATE(2026,10,22) -> 6 | M29: 33 | N29: 450 | O29: S200 - Login : 00 Chapters; PE : 33 Chapters; CE : 00 Chapters; Comp : 00 Chapters; Online Delivery : 00 Chapters | S29: Word
A30: =ROW()-1 -> 29 | B30: 717901_1_En | C30: Barla, Marco | D30: S5 | E30: 46316 | F30: =TODAY()-E30 -> 7 | M30: 21 | N30: 150 | S30: Word
A31: =ROW()-1 -> 30 | B31: 701850_1_En | C31: Zi,-PIC Yunlong 8770448 | D31: S5 | E31: 46321 | F31: =TODAY()-E31 -> 2 | M31: 12 | N31: 150 | S31: Word
A32: =ROW()-1 -> 31 | B32: 704476_1_En | C32: Zhan-Ventura, Michele Della-8770452 | D32: S5 | E32: 46322 | F32: =TODAY()-E32 -> 1 | M32: 20 | N32: 450 | S32: Word
A33: =ROW()-1 -> 32 | B33: 704485_1_En | C33: González, Carina S. González | D33: S50 | E33: 46322 | F33: =TODAY()-E33 -> 1 | M33: 16 | N33: 200 | S33: Word
A34: =ROW()-1 -> 33 | B34: 707996_1_En | C34: Ullah, Abrar | D34: S5
A35: =ROW()-1 -> 34 | B35: 697730_1_En | C35: Hameed, Alaa Ali | D35: S5 | T35: Rahul

Sheet Delivered
A1: S. no | B1: Book ID | C1: MPS ID | D1: Stage | E1: Received Date (S50) | F1: Total Avg. Aging Days | G1: Total Avg.Aging Days in S200 | H1: S300A TAT | I1: S300 TAT | J1: S600 TAT | K1: S650A TAT | L1: S650 TAT | M1: Total Chapters | N1: MS Pages | O1: TS Pages | P1: Status - S200 | Q1: Status - 300 | R1: Delivered Date | S1: Remarks
A2: 1 | B2: 704190_1_En | C2: Mindeguia-SCFE-8770433 | D2: S650 | E2: 46202 | F2: 63 | G2: 32 | H2: 11 | I2: 3 | J2: 6 | K2: 6 | L2: 5 | M2: 6 | N2: 184 | O2: =372+13 -> 385 | P2: S200 - Delivered on 30th July Login : 00 Chapters; PE : 00 Chapters; CE : 00 Chapters; Comp : 00 Chapters; Online Delivery : 00 Chapters | Q2: S300 - Comp : 00 Chapters; Online Delivery : 00 Chapters Delivered: 00 Chapters | R2: 46265
A3: 2 | B3: 703415_1_En | C3: Wen-NFE-8770557 | D3: S650 | E3: 46209 | F3: 62 | G3: =DATE(2026,8,1)-DATE(2026,7,8) -> 24 | H3: =DATE(2026,8,15)-DATE(2026,8,1) -> 14 | I3: =DATE(2026,8,21)-DATE(2026,8,20) -> 1 | J3: =DATE(2026,8,24)-DATE(2026,8,21) -> 3 | K3: =DATE(2026,8,31)-DATE(2026,8,24) -> 7 | L3: =DATE(2026,9,7)-DATE(2026,8,31) -> 7 | M3: 44 | N3: 569 | O3: =572+15 -> 587 | P3: S200 - Delivered on 01st Aug Login : 00 Chapters; PE : 00 Chapters; CE: 00 Chapters; Comp: 00 Chapters Online Delivery : 00 Chapters | Q3: S300 - Comp : 00 Chapters; Online Delivery : 00 Chapters Delivered: | R3: 46272
A4: 3 | B4: 701319_1_En | C4: Wang-AIS-Vol1-8770451 | D4: S650 | E4: 46195 | F4: 83 | G4: =DATE(2026,7,25)-DATE(2026,6,22) -> 33 | H4: =DATE(2026,8,7)-DATE(2026,7,25) -> 13 | I4: =DATE(2026,8,12)-DATE(2026,8,7) -> 5 | J4: =DATE(2026,8,25)-DATE(2026,8,12) -> 13 | K4: =DATE(2026,9,4)-DATE(2026,8,25) -> 10 | L4: =DATE(2026,9,12)-DATE(2026,9,4) -> 8 | M4: 66 | N4: 717 | O4: 719 | P4: S200 - Delivered on 25th July Login : 00 Chapters; PE : 00 Chapters; CE : 00 Chapters; Comp : 00 Chapters; Online Delivery : 00 Chapters | Q4: S300 - Delivered on 12th Aug Comp : 00 Chapters; Online Delivery : 00 Chapters Delivered: 00 Chapters | R4: 46277
A5: 4 | B5: 701541_1_En | C5: Wang-AIS-Vol2-8770450 | D5: S650 | E5: 46196 | F5: 81 | G5: =DATE(2026,7,30)-DATE(2026,6,24) -> 36 | H5: =DATE(2026,8,11)-DATE(2026,7,30) -> 12 | I5: =DATE(2026,8,19)-DATE(2026,8,11) -> 8 | J5: =DATE(2026,8,24)-DATE(2026,8,19) -> 5 | K5: =DATE(2026,9,4)-DATE(2026,8,24) -> 11 | L5: =DATE(2026,9,13)-DATE(2026,9,4) -> 9 | M5: 74 | N5: 826 | O5: =826+21 -> 847 | P5: S200 - Delivered on 30th July Login : 00 Chapters; PE : 00 Chapters; CE : 00 Chapters; Comp : 00 Chapters; Online Delivery : 00 Chapters | Q5: S300 - Comp : 00 Chapters; Online Delivery : 00 Chapters Delivered: 00 Chapters | R5: 46278
A6: 5 | B6: 701545_1_En | C6: Wang-AIS-Vol3-8770449 | D6: S650 | E6: 46195 | F6: 85 | G6: =DATE(2026,7,29)-DATE(2026,6,22) -> 37 | H6: =DATE(2026,8,11)-DATE(2026,7,29) -> 13 | I6: =DATE(2026,8,14)-DATE(2026,8,11) -> 3 | J6: =DATE(2026,8,24)-DATE(2026,8,14) -> 10 | K6: =DATE(2026,9,4)-DATE(2026,8,24) -> 11 | L6: =DATE(2026,9,15)-DATE(2026,9,4) -> 11 | M6: 65 | N6: 802 | O6: =766+19 -> 785 | P6: S200 - Delivered on 29th July Login : 00 Chapters; PE : 00 Chapters; CE : 00 Chapters; Comp : 00 Chapters; Online Delivery : 00 Chapters | Q6: S300 - Comp : 00 Chapters; Online Delivery : 00 Chapters Delivered: 00 Chapters | R6: 46280
A7: 6 | B7: 659832_1_En | C7: Iacomini-AIMN-8770513 | D7: S650 | E7: 46234 | F7: 52 | G7: =DATE(2026,8,24)-DATE(2026,7,31) -> 24 | H7: =DATE(2026,9,5)-DATE(2026,8,24) -> 12 | I7: =DATE(2026,9,9)-DATE(2026,9,5) -> 4 | J7: =DATE(2026,9,14)-DATE(2026,9,8) -> 6 | K7: =DATE(2026,9,17)-DATE(2026,9,14) -> 3 | L7: =DATE(2026,9,19)-DATE(2026,9,17) -> 2 | M7: 10 | N7: 250 | O7: =218+7 -> 225 | P7: S200 - Delivered on 24th Aug Login : 00 Chapters; PE : 00 Chapters; CE : 00 Chapters; Comp : 00 Chapters; Online Delivery : 00 Chapters | Q7: S300 - Comp : 02 Chapters; Online Delivery : 00 Chapters Delivered: 08 Chapters | R7: 46286
A8: 7 | B8: 688480_1_En | C8: Mukandavire, Zindoga | D8: S650 | E8: 46230 | F8: 58 | G8: =DATE(2026,8,17)-DATE(2026,7,27) -> 21 | H8: =DATE(2026,8,25)-DATE(2026,8,17) -> 8 | I8: =DATE(2026,9,8)-DATE(2026,8,27) -> 12 | J8: =DATE(2026,9,14)-DATE(2026,9,8) -> 6 | K8: =DATE(2026,9,23)-DATE(2026,9,14) -> 9 | L8: =DATE(2026,9,22)-DATE(2026,9,20) -> 2 | M8: 21 | N8: 780 | O8: =372+13 -> 385 | P8: S200 - Delivered on 17th Aug Login : 00 Chapters; PE : 00 Chapters; CE : 00 Chapters; Comp : 00 Chapters; Online Delivery : 00 Chapters | Q8: S300 - Comp : 00 Chapters; Online Delivery : FM Delivered: 20 Chapters | R8: 46288 | S8: Moved to accessibility on 21st
A9: =ROW()-1 -> 8 | B9: 710736_1_En | C9: Iadanza, Ernesto-8770689 | D9: S650 | E9: 46244 | F9: 47 | G9: =DATE(2026,8,31)-DATE(2026,8,12) -> 19 | H9: =DATE(2026,9,14)-DATE(2026,8,31) -> 14 | I9: =DATE(2026,9,15)-DATE(2026,9,14) -> 1 | J9: =DATE(2026,9,22)-DATE(2026,9,16) -> 6 | K9: =DATE(2026,9,23)-DATE(2026,9,22) -> 1 | L9: =DATE(2026,9,23)-DATE(2026,9,17) -> 6 | M9: 64 | N9: 700 | O9: =696+23 -> 719 | P9: S200 - Delivered on 31st Aug Login : 00 Chapters; PE : 00 Chapters; CE : 00 Chapters; Comp : 00 Chapters; Online Delivery : 00 Chapters | R9: 46291 | S9: Fixed Pub Date - 25th Sep
A10: =ROW()-1 -> 9 | B10: 710724_1_En | C10: Iadanza, Ernesto-8770719 | D10: S650 | E10: 46246 | F10: 44 | G10: =DATE(2026,8,27)-DATE(2026,8,12) -> 15 | H10: =DATE(2026,9,11)-DATE(2026,8,27) -> 15 | I10: =DATE(2026,9,16)-DATE(2026,9,14) -> 2 | J10: =DATE(2026,9,22)-DATE(2026,9,16) -> 6 | K10: =DATE(2026,9,23)-DATE(2026,9,22) -> 1 | L10: =DATE(2026,9,25)-DATE(2026,9,23) -> 2 | M10: 55 | N10: 700 | O10: =868+21 -> 889 | P10: S200 - Delivered on 27th Aug Login : 00 Chapters; PE : 00 Chapters; CE : 00 Chapters; Comp : 00 Chapters; Online Delivery : 00 Chapters | R10: 46290 | S10: Fixed Pub Date - 25th Sep
A11: =ROW()-1 -> 10 | B11: 710919_1_En | C11: Iadanza, Ernesto-8770888 | D11: S650 | E11: 46258 | F11: =DATE(2026,9,30)-DATE(2026,8,24) -> 37 | G11: =DATE(2026,9,9)-DATE(2026,8,24) -> 16 | H11: =DATE(2026,9,14)-DATE(2026,9,9) -> 5 | I11: =DATE(2026,9,15)-DATE(2026,9,14) -> 1 | J11: =DATE(2026,9,23)-DATE(2026,9,16) -> 7 | K11: =DATE(2026,9,23)-DATE(2026,9,23) -> 0 | L11: =DATE(2026,9,30)-DATE(2026,9,23) -> 7 | M11: 60 | N11: 500 | O11: =798+21 -> 819 | P11: S200 - Delivered on 9th Sep Login : 00 Chapters; PE : 00 Chapters; CE : 00 Chapters; Comp : 00 Chapters; Online Delivery : 00 Chapters | R11: 46295 | S11: Fixed Pub Date - 01st Oct- Jobsheet updation requitred, QIRA raised on 28th Sep
A12: =ROW()-1 -> 11 | B12: 706767_1_En | C12: Ivanov, Vitalii-V1 | D12: S650 | E12: 46252 | F12: =DATE(2026,10,3)-DATE(2026,8,18) -> 46 | G12: =DATE(2026,9,14)-DATE(2026,8,18) -> 27 | H12: =DATE(2026,9,18)-DATE(2026,9,14) -> 4 | I12: =DATE(2026,9,22)-DATE(2026,9,18) -> 4 | J12: =DATE(2026,9,26)-DATE(2026,9,22) -> 4 | K12: =DATE(2026,9,29)-DATE(2026,9,26) -> 3 | L12: =DATE(2026,10,1)-DATE(2026,9,29) -> 2 | M12: 25 | N12: 500 | O12: =446+19 -> 465 | P12: S200 - Login : 00 Chapters; PE : 00 Chapters; CE : 00 Chapters; Comp : 00 Chapters; Online Delivery : 00 Chapters | R12: 46298 | S12: Fixed Pub Date - 24th Sep, S600 awaited (Job sheet issue)
A13: =ROW()-1 -> 12 | B13: 706769_1_En | C13: Ivanov, Vitalii-V2 | D13: S650 | E13: 46254 | F13: =DATE(2026,10,1)-DATE(2026,8,20) -> 42 | G13: =DATE(2026,9,14)-DATE(2026,8,20) -> 25 | H13: =DATE(2026,9,17)-DATE(2026,9,12) -> 5 | I13: =DATE(2026,9,24)-DATE(2026,9,22) -> 2 | J13: =DATE(2026,9,24)-DATE(2026,9,24) -> 0 | K13: =DATE(2026,9,25)-DATE(2026,9,24) -> 1 | L13: 8 | M13: 25 | N13: 500 | O13: =276+19 -> 295 | P13: S200 - Login : 00 Chapters; PE : 00 Chapters; CE : 00 Chapters; Comp : 00 Chapters; Online Delivery : 00 Chapters | R13: 46296 | S13: Fixed Pub Date - 24th Sep
A14: =ROW()-1 -> 13 | B14: 706770_1_En | C14: Ivanov, Vitalii-V3 | D14: S650 | E14: 46259 | F14: =DATE(2026,10,1)-DATE(2026,8,25) -> 37 | G14: =DATE(2026,9,12)-DATE(2026,8,24) -> 19 | H14: =DATE(2026,9,17)-DATE(2026,9,12) -> 5 | I14: =DATE(2026,9,17)-DATE(2026,9,17) -> 0 | J14: =DATE(2026,9,22)-DATE(2026,9,18) -> 4 | K14: =DATE(2026,9,24)-DATE(2026,9,22) -> 2 | L14: =DATE(2026,9,30)-DATE(2026,9,25) -> 5 | M14: 35 | N14: 500 | O14: =324+19 -> 343 | P14: S200 - Login : 00 Chapters; PE : 00 Chapters; CE : 00 Chapters; Comp : 00 Chapters; Online Delivery : 00 Chapters | R14: 46296 | S14: Fixed Pub Date - 24th Sep
A15: =ROW()-1 -> 14 | B15: 634063_1_En | C15: Tortorella-PGMP1-8770423 | D15: S650 | E15: 46204 | F15: =DATE(2026,10,6)-E15 -> 97 | G15: =DATE(2026,8,3)-DATE(2026,7,1) -> 33 | H15: =DATE(2026,8,27)-DATE(2026,8,3) -> 24 | I15: =DATE(2026,9,3)-DATE(2026,8,27) -> 7 | J15: =DATE(2026,9,10)-DATE(2026,9,3) -> 7 | K15: =DATE(2026,9,30)-DATE(2026,9,12) -> 18 | L15: =DATE(2026,10,7)-DATE(2026,9,30) -> 7 | M15: =DATE(2026,10,6)-DATE(2026,10,4) -> 2 | N15: 317 | O15: 299 | P15: S200 - Delivered on 03rd Aug Login : 00 Chapters; PE : 00 Chapters; CE : 00 Chapters; Comp : 00 Chapters; Online Delivery : 00 Chapters | Q15: S300 - Comp : 00 Chapters; Online Delivery : 00 Chapters Delivered: 00 Chapters | R15: 46301
A16: =ROW()-1 -> 15 | B16: 702137_1_En | C16: Tortorella-PGMP2-8770424 | D16: S650 | E16: 46204 | F16: =DATE(2026,10,12)-E16 -> 103 | G16: 35 | H16: 23 | I16: 10 | J16: 4 | K16: 18 | L16: 5 | M16: 6 | N16: 302 | O16: 333 | P16: S200 - Delivered on 05th Aug Login : 00 Chapters; PE : 00 Chapters; CE : 00 Chapters; Comp : 00 Chapters; Online Delivery : 00 Chapters | Q16: S300 - Comp : 00 Chapters; Online Delivery : 01 Chapters Delivered: 05 Chapters | R16: 46307
A17: =ROW()-1 -> 16 | B17: 703192_1_En | C17: Bhat, Vijay Kumar | D17: S650 | E17: 46265 | F17: =DATE(2026,10,14)-E17 -> 44 | G17: =DATE(2026,9,24)-DATE(2026,8,24) -> 31 | H17: =DATE(2026,9,30)-DATE(2026,9,24) -> 6 | I17: =DATE(2026,10,3)-DATE(2026,10,1) -> 2 | J17: =DATE(2026,10,7)-DATE(2026,10,4) -> 3 | K17: =DATE(2026,10,10)-DATE(2026,10,7) -> 3 | L17: =DATE(2026,10,14)-DATE(2026,10,10) -> 4 | M17: 25 | N17: 500 | O17: 385 | P17: S200 - Login : 00 Chapters; PE : 00 Chapters; CE : 00 Chapters; Comp : 00 Chapters; Online Delivery : 00 Chapters | R17: 46309
A18: =ROW()-1 -> 17 | B18: 691371_1_En | C18: Zawawi, Iskandar Shah Mohd | D18: S650 | E18: 46269 | F18: =DATE(2026,10,26)-E18 -> 52 | G18: =DATE(2026,9,26)-DATE(2026,9,4) -> 22 | H18: =DATE(2026,10,11)-DATE(2026,9,26) -> 15 | I18: =DATE(2026,10,16)-DATE(2026,10,12) -> 4 | J18: =DATE(2026,10,23)-DATE(2026,10,16) -> 7 | K18: =DATE(2026,10,26)-DATE(2026,10,23) -> 3 | L18: =DATE(2026,10,27)-DATE(2026,10,26) -> 1 | M18: 14 | N18: 189 | O18: 201 | P18: S200 - Login : 00 Chapters; PE : 00 Chapters; CE : 00 Chapters; Comp : 00 Chapters; Online Delivery : 00 Chapters | R18: 46321

Sheet Summary
A1: DESCriptions | B1: Column1 | C1: Overall Avg. Aging days
A2: SUMMARY | C2: Overall Avg. Aging days
A3: Total No of Titles in WIP | B3: =COUNTA(Table2[MPS ID]) -> 34 | C3: =AVERAGE(Table2[Current TAT (S50 onward)]) -> 24.46875
A4: Total Titles Delivered | B4: =COUNTA(Delivered!C2:C18) -> 17 | C4: =AVERAGE(Table3[Total Avg. Aging Days]) -> 61.3125
A6: Month/No Of Titles | B6: S200 | C6: S300A | D6: S300 | E6: S600 | F6: S650A | G6: S650 | H6: Total Monthly Avg. Aging days
A7: Aug, 1 Book | B7: =Delivered!G2 -> 32 | C7: =Delivered!H2 -> 11 | D7: =Delivered!I2 -> 3 | E7: =Delivered!J2 -> 6 | F7: =Delivered!K2 -> 6 | G7: =Delivered!L2 -> 5 | H7: 63
A8: Sep, 9 Books | B8: =AVERAGE(Delivered!G3:G11) -> 25 | C8: =AVERAGE(Delivered!H3:H11) -> 11.777778 | D8: =AVERAGE(Delivered!I3:I11) -> 4.1111111 | E8: =AVERAGE(Delivered!J3:J11) -> 6.8888889 | F8: =AVERAGE(Delivered!K3:K11) -> 5.8888889 | G8: =AVERAGE(Delivered!L3:L11) -> 6 | H8: 61
A9: Oct 7 Books | B9: =AVERAGE(Delivered!G12:G21) -> 27.428571 | C9: =AVERAGE(Delivered!H12:H21) -> 11.714286 | D9: =AVERAGE(Delivered!I12:I21) -> 4.1428571 | E9: =AVERAGE(Delivered!J12:J21) -> 4.1428571 | F9: =AVERAGE(Delivered!K12:K21) -> 6.8571429 | G9: =AVERAGE(Delivered!L12:L21) -> 4.5714286 | H9: 60
A10: Average Aging Days for past months | B10: =AVERAGE(B7:B9) -> 28.142857 | C10: =AVERAGE(C7:C9) -> 11.497354 | D10: =AVERAGE(D7:D9) -> 3.7513228 | E10: =AVERAGE(E7:E9) -> 5.6772487 | F10: =AVERAGE(F7:F9) -> 6.2486772 | G10: =AVERAGE(G7:G9) -> 5.1904762
A12: Shortest TAT | B12: 37
A13: Longest TAT | B13: 103
A15: S200 | B15: 13 Books
A16: S300A | B16: 3 Books
A17: S300 | B17: 7 Books
A18: S600 | B18: 2
A19: S650 A | B19: 2
A20: S650 | B20: 1

Sheet Month Wise Delivery Status
B3: Month Wise Delivery Status
B4: Total No.of Titles | C4: 15
B5: Month | C5: No of titles delivered
B6: 46235 | C6: =COUNTIFS(Delivered!$R:$R,">="&B6,Delivered!$R:$R,"<"&EDATE(B6,1)) -> 1
B7: 46266 | C7: =COUNTIFS(Delivered!$R:$R,">="&B7,Delivered!$R:$R,"<"&EDATE(B7,1)) -> 9
B8: 46296 | C8: =COUNTIFS(Delivered!$R:$R,">="&B8,Delivered!$R:$R,"<"&EDATE(B8,1)) -> 7
B9: 46327 | C9: =COUNTIFS(Delivered!$R:$R,">="&B9,Delivered!$R:$R,"<"&EDATE(B9,1)) -> 0
B10: 46357 | C10: =COUNTIFS(Delivered!$R:$R,">="&B10,Delivered!$R:$R,"<"&EDATE(B10,1)) -> 0

Sheet MISC
A1: S. no | B1: Book ID | C1: S300A TAT(Target:10) | D1: S300 TAT(Target:7) | E1: S600 TAT(Target:7) | F1: S650 TAT(Target:7) | G1: Total TAT | H1: Action Required | I1: Remarks
A2: 1 | B2: 634063_1_En | C2: =DATE(2026,8,27)-DATE(2026,8,3) -> 24 | D2: =DATE(2026,9,3)-DATE(2026,8,27) -> 7 | E2: =DATE(2026,9,10)-DATE(2026,9,3) -> 7 | G2: =TODAY()-#REF! -> #REF! | H2: =IF(SUM(C2:F2)=0, "Not Started", IF(SUM(C2:F2)<=75, "On Track. "&(75-SUM(C2:F2))&" days buffer", "Recover "&(SUM(C2:F2)-75)&" days!")) -> On Track. 37 days buffer
A3: 2 | B3: 702137_1_En | C3: =DATE(2026,8,28)-DATE(2026,8,5) -> 23 | D3: =DATE(2026,9,8)-DATE(2026,8,29) -> 10 | E3: =DATE(2026,9,12)-DATE(2026,9,8) -> 4 | G3: =TODAY()-#REF! -> #REF! | H3: =IF(SUM(C3:F3)=0, "Not Started", IF(SUM(C3:F3)<=75, "On Track. "&(75-SUM(C3:F3))&" days buffer", "Recover "&(SUM(C3:F3)-75)&" days!")) -> On Track. 38 days buffer
A4: 3 | B4: 688480_1_En | C4: =DATE(2026,8,25)-DATE(2026,8,17) -> 8 | D4: =DATE(2026,9,8)-DATE(2026,8,27) -> 12 | E4: =DATE(2026,9,14)-DATE(2026,9,8) -> 6 | F4: =DATE(2026,9,22)-DATE(2026,9,20) -> 2 | G4: =DATE(2026,9,23)-DATE(2026,7,27) -> 58 | H4: =IF(SUM(C4:F4)=0, "Not Started", IF(SUM(C4:F4)<=75, "On Track. "&(75-SUM(C4:F4))&" days buffer", "Recover "&(G4-75)&" days!")) -> On Track. 47 days buffer | I4: Released on 22-Sep
A5: 4 | B5: 659832_1_En | C5: =DATE(2026,9,5)-DATE(2026,8,24) -> 12 | D5: =DATE(2026,9,9)-DATE(2026,9,5) -> 4 | E5: =DATE(2026,9,14)-DATE(2026,9,8) -> 6 | F5: =DATE(2026,9,20)-DATE(2026,9,17) -> 3 | G5: =DATE(2026,9,21)-DATE(2026,7,31) -> 52 | H5: =IF(SUM(C5:F5)=0, "Not Started", IF(SUM(C5:F5)<=75, "On Track. "&(75-SUM(C5:F5))&" days buffer", "Recover "&(SUM(C5:F5)-75)&" days!")) -> On Track. 50 days buffer | I5: Released on 21-Sep
A6: 5 | B6: 710724_1_En | C6: =DATE(2026,9,11)-DATE(2026,8,27) -> 15 | D6: =DATE(2026,9,15)-DATE(2026,9,14) -> 1 | E6: =DATE(2026,9,14)-DATE(2026,9,8) -> 6 | F6: =DATE(2026,9,26)-DATE(2026,9,22) -> 4 | G6: =DATE(2026,9,25)-DATE(2026,8,12) -> 44 | H6: =IF(SUM(C6:F6)=0, "Not Started", IF(SUM(C6:F6)<=75, "On Track. "&(75-SUM(C6:F6))&" days buffer", "Recover "&(SUM(C6:F6)-75)&" days!")) -> On Track. 49 days buffer | I6: Released on 25-Sep
A7: 6 | B7: 710736_1_En | C7: =DATE(2026,9,14)-DATE(2026,8,31) -> 14 | D7: =DATE(2026,9,15)-DATE(2026,9,14) -> 1 | E7: =DATE(2026,9,22)-DATE(2026,9,16) -> 6 | F7: =DATE(2026,9,22)-DATE(2026,9,16) -> 6 | G7: =DATE(2026,9,26)-DATE(2026,8,10) -> 47 | H7: =IF(SUM(C7:F7)=0, "Not Started", IF(SUM(C7:F7)<=75, "On Track. "&(75-SUM(C7:F7))&" days buffer", "Recover "&(SUM(C7:F7)-75)&" days!")) -> On Track. 48 days buffer | I7: Released on 26-Sep
A8: 7 | B8: 706770_1_En | C8: =DATE(2026,9,17)-DATE(2026,9,12) -> 5 | D8: =DATE(2026,9,17)-DATE(2026,9,17) -> 0 | E8: =DATE(2026,9,22)-DATE(2026,9,18) -> 4 | F8: =TODAY()-DATE(2026,9,25) -> 33 | G8: =TODAY()-#REF! -> #REF! | H8: =IF(SUM(C8:F8)=0, "Not Started", IF(SUM(C8:F8)<=75, "On Track. "&(75-SUM(C8:F8))&" days buffer", "Recover "&(SUM(C8:F8)-75)&" days!")) -> On Track. 33 days buffer
A9: 8 | B9: 706769_1_En | C9: =TRIM(DATE(2026,9,17)-DATE(2026,9,12)) -> 5 | D9: =TODAY()-DATE(2026,9,17) -> 41 | G9: =TODAY()-#REF! -> #REF! | H9: =IF(SUM(C9:F9)=0, "Not Started", IF(SUM(C9:F9)<=75, "On Track. "&(75-SUM(C9:F9))&" days buffer", "Recover "&(SUM(C9:F9)-75)&" days!")) -> On Track. 34 days buffer
A10: 9 | B10: 706767_1_En | C10: =TRIM(DATE(2026,9,17)-DATE(2026,9,12)) -> 5 | D10: =TODAY()-DATE(2026,9,17) -> 41 | G10: =TODAY()-#REF! -> #REF! | H10: =IF(SUM(C10:F10)=0, "Not Started", IF(SUM(C10:F10)<=75, "On Track. "&(75-SUM(C10:F10))&" days buffer", "Recover "&(SUM(C10:F10)-75)&" days!")) -> On Track. 34 days buffer
A11: 10 | B11: 710919_1_En | C11: =TRIM(DATE(2026,9,14)-DATE(2026,9,9)) -> 5 | D11: =DATE(2026,9,15)-DATE(2026,9,14) -> 1 | E11: =TODAY()-DATE(2026,9,16) -> 42 | G11: =TODAY()-#REF! -> #REF! | H11: =IF(SUM(C11:F11)=0, "Not Started", IF(SUM(C11:F11)<=75, "On Track. "&(75-SUM(C11:F11))&" days buffer", "Recover "&(SUM(C11:F11)-75)&" days!")) -> On Track. 32 days buffer
A12: 11 | B12: 705744_1_En | G12: =TODAY()-#REF! -> #REF! | H12: =IF(SUM(C12:F12)=0, "Not Started", IF(SUM(C12:F12)<=75, "On Track. "&(75-SUM(C12:F12))&" days buffer", "Recover "&(SUM(C12:F12)-75)&" days!")) -> Not Started
A13: 12 | B13: 703192_1_En | G13: =TODAY()-#REF! -> #REF! | H13: =IF(SUM(C13:F13)=0, "Not Started", IF(SUM(C13:F13)<=75, "On Track. "&(75-SUM(C13:F13))&" days buffer", "Recover "&(SUM(C13:F13)-75)&" days!")) -> Not Started
A14: 13 | B14: 691371_1_En | G14: =TODAY()-#REF! -> #REF! | H14: =IF(SUM(C14:F14)=0, "Not Started", IF(SUM(C14:F14)<=75, "On Track. "&(75-SUM(C14:F14))&" days buffer", "Recover "&(SUM(C14:F14)-75)&" days!")) -> Not Started
A15: 14 | B15: 695893_1_En | G15: =TODAY()-#REF! -> #REF! | H15: =IF(SUM(C15:F15)=0, "Not Started", IF(SUM(C15:F15)<=75, "On Track. "&(75-SUM(C15:F15))&" days buffer", "Recover "&(SUM(C15:F15)-75)&" days!")) -> Not Started
A16: 15 | B16: 695444_1_En | G16: =TODAY()-#REF! -> #REF! | H16: =IF(SUM(C16:F16)=0, "Not Started", IF(SUM(C16:F16)<=75, "On Track. "&(75-SUM(C16:F16))&" days buffer", "Recover "&(SUM(C16:F16)-75)&" days!")) -> Not Started
A17: 16 | B17: 695897_1_En | G17: =TODAY()-#REF! -> #REF! | H17: =IF(SUM(C17:F17)=0, "Not Started", IF(SUM(C17:F17)<=75, "On Track. "&(75-SUM(C17:F17))&" days buffer", "Recover "&(SUM(C17:F17)-75)&" days!")) -> Not Started
A18: 17 | B18: 696264_1_En | G18: =TODAY()-#REF! -> #REF! | H18: =IF(SUM(C18:F18)=0, "Not Started", IF(SUM(C18:F18)<=75, "On Track. "&(75-SUM(C18:F18))&" days buffer", "Recover "&(SUM(C18:F18)-75)&" days!")) -> Not Started
A19: 18 | B19: 696262_1_En | G19: =TODAY()-#REF! -> #REF! | H19: =IF(SUM(C19:F19)=0, "Not Started", IF(SUM(C19:F19)<=75, "On Track. "&(75-SUM(C19:F19))&" days buffer", "Recover "&(SUM(C19:F19)-75)&" days!")) -> Not Started
A20: 19 | B20: 696258_1_En | G20: =TODAY()-#REF! -> #REF! | H20: =IF(SUM(C20:F20)=0, "Not Started", IF(SUM(C20:F20)<=75, "On Track. "&(75-SUM(C20:F20))&" days buffer", "Recover "&(SUM(C20:F20)-75)&" days!")) -> Not Started
A21: 20 | B21: 696260_1_En | G21: =TODAY()-#REF! -> #REF! | H21: =IF(SUM(C21:F21)=0, "Not Started", IF(SUM(C21:F21)<=75, "On Track. "&(75-SUM(C21:F21))&" days buffer", "Recover "&(SUM(C21:F21)-75)&" days!")) -> Not Started
A22: 21 | B22: 696253_1_En | G22: =TODAY()-#REF! -> #REF!
A23: 22 | B23: 708036_1_En | G23: =TODAY()-#REF! -> #REF!
A24: 23 | B24: 702839_1_En | G24: =TODAY()-#REF! -> #REF!
A25: 24 | B25: 704353_1_En | G25: =TODAY()-#REF! -> #REF!
A26: 25 | B26: 708652_1_En
A27: 26 | B27: 709492_1_En
A28: 27 | B28: 702446_1_En
C46: WIP | D46: =COUNTA(D49:D81) -> 33
C47: Delivered | D47: 17 | E47: Overall Avg. Aging 61 days
B48: SL. No | C48: MPS ID | D48: Stage | E48: Current TAT (S50 onward) | F48: Remarks
B49: 1 | C49: Sánchez, Angeles | D49: S600 | E49: 64
B50: 2 | C50: Giordano, Andrea | D50: S650A | E50: 40
B51: 3 | C51: Metsoc Vol-V-8771050 | D51: S300 | E51: 39
B52: 4 | C52: Metsoc Vol-VI-8771051 | D52: S600 | E52: 39
B53: 5 | C53: Metsoc Vol-VII-8771052 | D53: S300 | E53: 39
B54: 6 | C54: Abarzhi, Snezhana I. | D54: S650A | E54: 36 | G54: 696263_1_En | H54: MetSoc-Vol9-8771159 | I54: 30 | J54: PageProof-S200 | K54: PMApproval
B55: 7 | C55: Metsoc Vol-III-8771048 | D55: S300 | E55: 34 | G55: 696263_1_En | H55: MetSoc-Vol9-8771159 | I55: 46 | J55: PageProof-S200 | K55: PMApproval
B56: 8 | C56: Metsoc Vol-IV-8771049 | D56: S300A | E56: 34 | G56: 696263_1_En | H56: etSoc-Vol9-8771159 | I56: 58 | J56: PageProof-S200 | K56: PMApproval
B57: 9 | C57: Metsoc Vol-VIII-8771060 | D57: S300 | E57: 33
...
